[2024-10-03T04:51:00.516+0000] {taskinstance.py:1159} INFO - Dependencies all met for dep_context=non-requeueable deps ti=<TaskInstance: eia_data_pipeline.fetch_api1_data scheduled__2024-10-01T00:00:00+00:00 [queued]>
[2024-10-03T04:51:00.565+0000] {taskinstance.py:1159} INFO - Dependencies all met for dep_context=requeueable deps ti=<TaskInstance: eia_data_pipeline.fetch_api1_data scheduled__2024-10-01T00:00:00+00:00 [queued]>
[2024-10-03T04:51:00.566+0000] {taskinstance.py:1361} INFO - Starting attempt 2 of 2
[2024-10-03T04:51:00.607+0000] {taskinstance.py:1382} INFO - Executing <Task(PythonOperator): fetch_api1_data> on 2024-10-01 00:00:00+00:00
[2024-10-03T04:51:00.640+0000] {standard_task_runner.py:57} INFO - Started process 65 to run task
[2024-10-03T04:51:00.661+0000] {standard_task_runner.py:84} INFO - Running: ['***', 'tasks', 'run', 'eia_data_pipeline', 'fetch_api1_data', 'scheduled__2024-10-01T00:00:00+00:00', '--job-id', '16', '--raw', '--subdir', 'DAGS_FOLDER/new.py', '--cfg-path', '/tmp/tmpt2fksh4c']
[2024-10-03T04:51:00.699+0000] {standard_task_runner.py:85} INFO - Job 16: Subtask fetch_api1_data
[2024-10-03T04:51:00.966+0000] {task_command.py:415} INFO - Running <TaskInstance: eia_data_pipeline.fetch_api1_data scheduled__2024-10-01T00:00:00+00:00 [running]> on host 05505aab1039
[2024-10-03T04:51:07.212+0000] {taskinstance.py:1660} INFO - Exporting env vars: AIRFLOW_CTX_DAG_OWNER='***' AIRFLOW_CTX_DAG_ID='eia_data_pipeline' AIRFLOW_CTX_TASK_ID='fetch_api1_data' AIRFLOW_CTX_EXECUTION_DATE='2024-10-01T00:00:00+00:00' AIRFLOW_CTX_TRY_NUMBER='2' AIRFLOW_CTX_DAG_RUN_ID='scheduled__2024-10-01T00:00:00+00:00'
[2024-10-03T04:51:15.855+0000] {taskinstance.py:1943} ERROR - Task failed with exception
Traceback (most recent call last):
  File "/home/airflow/.local/lib/python3.8/site-packages/airflow/operators/python.py", line 192, in execute
    return_value = self.execute_callable()
  File "/home/airflow/.local/lib/python3.8/site-packages/airflow/operators/python.py", line 209, in execute_callable
    return self.python_callable(*self.op_args, **self.op_kwargs)
  File "/opt/airflow/dags/new.py", line 62, in fetch_and_store_data
    mysql_connect(data, table_name)
  File "/opt/airflow/dags/new.py", line 56, in mysql_connect
    engine = create_engine(mysql_connection_string)
  File "<string>", line 2, in create_engine
  File "/home/airflow/.local/lib/python3.8/site-packages/sqlalchemy/util/deprecations.py", line 375, in warned
    return fn(*args, **kwargs)
  File "/home/airflow/.local/lib/python3.8/site-packages/sqlalchemy/engine/create.py", line 544, in create_engine
    dbapi = dialect_cls.dbapi(**dbapi_args)
  File "/home/airflow/.local/lib/python3.8/site-packages/sqlalchemy/dialects/mysql/pymysql.py", line 80, in dbapi
    return __import__("pymysql")
ModuleNotFoundError: No module named 'pymysql'
[2024-10-03T04:51:16.007+0000] {taskinstance.py:1400} INFO - Marking task as FAILED. dag_id=eia_data_pipeline, task_id=fetch_api1_data, execution_date=20241001T000000, start_date=20241003T045100, end_date=20241003T045116
[2024-10-03T04:51:16.130+0000] {standard_task_runner.py:104} ERROR - Failed to execute job 16 for task fetch_api1_data (No module named 'pymysql'; 65)
[2024-10-03T04:51:16.267+0000] {local_task_job_runner.py:228} INFO - Task exited with return code 1
[2024-10-03T04:51:16.407+0000] {taskinstance.py:2784} INFO - 0 downstream tasks scheduled from follow-on schedule check
