[2024-10-01T10:39:27.900+0000] {taskinstance.py:1159} INFO - Dependencies all met for dep_context=non-requeueable deps ti=<TaskInstance: eia_data_pipeline.fetch_api1_data manual__2024-10-01T10:33:33.565458+00:00 [queued]>
[2024-10-01T10:39:27.925+0000] {taskinstance.py:1159} INFO - Dependencies all met for dep_context=requeueable deps ti=<TaskInstance: eia_data_pipeline.fetch_api1_data manual__2024-10-01T10:33:33.565458+00:00 [queued]>
[2024-10-01T10:39:27.927+0000] {taskinstance.py:1361} INFO - Starting attempt 2 of 2
[2024-10-01T10:39:27.956+0000] {taskinstance.py:1382} INFO - Executing <Task(PythonOperator): fetch_api1_data> on 2024-10-01 10:33:33.565458+00:00
[2024-10-01T10:39:27.980+0000] {standard_task_runner.py:57} INFO - Started process 62 to run task
[2024-10-01T10:39:27.982+0000] {standard_task_runner.py:84} INFO - Running: ['***', 'tasks', 'run', 'eia_data_pipeline', 'fetch_api1_data', 'manual__2024-10-01T10:33:33.565458+00:00', '--job-id', '10', '--raw', '--subdir', 'DAGS_FOLDER/new.py', '--cfg-path', '/tmp/tmp76yp09sx']
[2024-10-01T10:39:27.998+0000] {standard_task_runner.py:85} INFO - Job 10: Subtask fetch_api1_data
[2024-10-01T10:39:28.200+0000] {task_command.py:415} INFO - Running <TaskInstance: eia_data_pipeline.fetch_api1_data manual__2024-10-01T10:33:33.565458+00:00 [running]> on host 05505aab1039
[2024-10-01T10:39:30.312+0000] {taskinstance.py:1660} INFO - Exporting env vars: AIRFLOW_CTX_DAG_OWNER='***' AIRFLOW_CTX_DAG_ID='eia_data_pipeline' AIRFLOW_CTX_TASK_ID='fetch_api1_data' AIRFLOW_CTX_EXECUTION_DATE='2024-10-01T10:33:33.565458+00:00' AIRFLOW_CTX_TRY_NUMBER='2' AIRFLOW_CTX_DAG_RUN_ID='manual__2024-10-01T10:33:33.565458+00:00'
[2024-10-01T10:39:41.948+0000] {taskinstance.py:1943} ERROR - Task failed with exception
Traceback (most recent call last):
  File "/home/airflow/.local/lib/python3.8/site-packages/airflow/operators/python.py", line 192, in execute
    return_value = self.execute_callable()
  File "/home/airflow/.local/lib/python3.8/site-packages/airflow/operators/python.py", line 209, in execute_callable
    return self.python_callable(*self.op_args, **self.op_kwargs)
  File "/opt/airflow/dags/new.py", line 62, in fetch_and_store_data
    mysql_connect(data, table_name)
  File "/opt/airflow/dags/new.py", line 56, in mysql_connect
    engine = create_engine(mysql_connection_string)
  File "<string>", line 2, in create_engine
  File "/home/airflow/.local/lib/python3.8/site-packages/sqlalchemy/util/deprecations.py", line 375, in warned
    return fn(*args, **kwargs)
  File "/home/airflow/.local/lib/python3.8/site-packages/sqlalchemy/engine/create.py", line 544, in create_engine
    dbapi = dialect_cls.dbapi(**dbapi_args)
  File "/home/airflow/.local/lib/python3.8/site-packages/sqlalchemy/dialects/mysql/pymysql.py", line 80, in dbapi
    return __import__("pymysql")
ModuleNotFoundError: No module named 'pymysql'
[2024-10-01T10:39:41.992+0000] {taskinstance.py:1400} INFO - Marking task as FAILED. dag_id=eia_data_pipeline, task_id=fetch_api1_data, execution_date=20241001T103333, start_date=20241001T103927, end_date=20241001T103941
[2024-10-01T10:39:42.036+0000] {standard_task_runner.py:104} ERROR - Failed to execute job 10 for task fetch_api1_data (No module named 'pymysql'; 62)
[2024-10-01T10:39:42.096+0000] {local_task_job_runner.py:228} INFO - Task exited with return code 1
[2024-10-01T10:39:42.139+0000] {taskinstance.py:2784} INFO - 0 downstream tasks scheduled from follow-on schedule check
